Workbook
Name Slicer_Diabetes_Status: #N/A
Name Slicer_Weight_Status: #N/A

Sheet Patient Directory
A1: Patient ID | B1: Full Name
A2: PT00001 | B2: Allison Hill
A3: PT00002 | B3: Noah Rhodes
A4: PT00003 | B4: Angie Henderson
A5: PT00004 | B5: Daniel Wagner
A6: PT00005 | B6: Cristian Santos
A7: PT00006 | B7: Connie Lawrence
A8: PT00007 | B8: Abigail Shaffer
A9: PT00008 | B9: Gina Moore
A10: PT00009 | B10: Gabrielle Davis
A11: PT00010 | B11: Ryan Munoz
A12: PT00011 | B12: Monica Herrera
... A2336: PT02335 | B2336: Scott Stewart

Sheet Clinical Assessments
A1: Patient ID | B1: BMI | C1: HbA1c Level | D1: Cardiac Condition | E1: Organ Transplant History | F1: Cancer History | G1: Major Surgeries Count | H1: Tobacco Use
A2: PT00001 | B2: 31.57 | C2: 6.36 | D2: No | E2: No | F2: No | G2: 1 | H2: No
A3: PT00002 | B3: 22.43 | C3: 11.46 | D3: No | E3: No | F3: No | G3: None | H3: Yes
A4: PT00003 | B4: 34.6 | C4: 7.79 | D4: No | E4: No | F4: Yes | G4: 1 | H4: No
A5: PT00004 | B5: 35.9 | C5: 8.19 | D5: No | E5: Yes | F5: No | G5: 1 | H5: Yes
A6: PT00005 | B6: 16.23 | C6: 7.8 | D6: No | E6: No | F6: No | G6: 1 | H6: Yes
A7: PT00006 | B7: 20.65 | C7: 9.01 | D7: No | E7: No | F7: No | G7: None | H7: Yes
A8: PT00007 | B8: 30.37 | C8: 5.84 | D8: Yes | E8: No | F8: No | G8: None | H8: No
A9: PT00008 | B9: 27.35 | C9: 4 | D9: No | E9: No | F9: Yes | G9: None | H9: No
A10: PT00009 | B10: 29.39 | C10: 5.84 | D10: No | E10: No | F10: No | G10: 2 | H10: No
A11: PT00010 | B11: 23.7 | C11: 7.74 | D11: No | E11: No | F11: No | G11: None | H11: No
A12: PT00011 | B12: 35.48 | C12: 4.36 | D12: No | E12: No | F12: No | G12: 1 | H12: Yes
A13: PT00012 | B13: 34.79 | C13: 5.86 | D13: No | E13: No | F13: No | G13: 1 | H13: No
... A2336: PT02335 | B2336: 26.16 | C2336: 4.7 | D2336: No | E2336: No | F2336: No | G2336: None | H2336: Yes

Sheet Admission Records
A1: Patient ID | B1: Admission Year | C1: Admission Month | D1: Admission Day | E1: Dependents | F1: Billed Amount | G1: Facility Tier | H1: City Tier | I1: Region Code
A2: PT01684 | B2: 1995 | C2: Jul | D2: 15 | E2: 0 | F2: 2652.98 | G2: Tier 2 | H2: Tier 2 | I2: ZN2015
A3: PT01117 | B3: 2005 | C3: Jan | D3: 25 | E3: 1 | F3: 51222.9 | G3: Tier 1 | H3: Tier 2 | I3: ZN2015
A4: PT01854 | B4: 1998 | C4: Sep | D4: 20 | E4: 0 | F4: 2553.18 | G4: Tier 2 | H4: Tier 2 | I4: ZN2011
A5: PT00324 | B5: 2010 | C5: Nov | D5: 11 | E5: 2 | F5: 9165.2 | G5: Tier 2 | H5: Tier 3 | I5: ZN2015
A6: PT02302 | B6: 2002 | C6: Jun | D6: 21 | E6: 3 | F6: 9085.25 | G6: Tier 2 | H6: Tier 1 | I6: ZN2008
A7: PT01106 | B7: 2007 | C7: Dec | D7: 15 | E7: 1 | F7: 10796.79 | G7: Tier 2 | H7: Tier 3 | I7: ZN2005
A8: PT00592 | B8: 2002 | C8: Jun | D8: 7 | E8: 2 | F8: 6855.02 | G8: Tier 1 | H8: Tier 1 | I8: ZN2005
A9: PT00848 | B9: 2003 | C9: Jan | D9: 1 | E9: 3 | F9: 6908.88 | G9: Tier 1 | H9: Tier 2 | I9: ZN2002
A10: PT01965 | B10: 2002 | C10: Feb | D10: 1 | E10: 2 | F10: 8134.01 | G10: Tier 1 | H10: Tier 3 | I10: ZN2017
A11: PT01658 | B11: 2000 | C11: Jan | D11: 7 | E11: 0 | F11: 10508.1 | G11: Tier 3 | H11: Tier 1 | I11: ZN2006
A12: PT00402 | B12: 2022 | C12: Apr | D12: 23 | E12: 1 | F12: 7321.99 | G12: Tier 2 | H12: Tier 1 | I12: ZN2019
A13: PT02312 | B13: 1995 | C13: May | D13: 13 | E13: 0 | F13: 6965.53 | G13: Tier 2 | H13: Tier 3 | I13: ZN2005
... A27: PT01397 | B27: 2021 | C27: Feb | D27: 1 | E27: 2 | F27: 10412.05 | G27: Tier 1 | H27: Tier 1 | I27: ZN2002
A28: PT00270 | B28: ? | C28: Aug | D28: 8 | E28: 0 | F28: 12781.49 | G28: Tier 2 | H28: Tier 3 | I28: ZN2013
A29: PT02053 | B29: 2001 | C29: Jul | D29: 24 | E29: 2 | F29: 2689.91 | G29: Tier 1 | H29: Tier 2 | I29: ZN2005
A30: PT00651 | B30: 2018 | C30: Sep | D30: 22 | E30: 0 | F30: 25806.2 | G30: Tier 1 | H30: Tier 2 | I30: ZN2018
A31: PT01397 | B31: 2001 | C31: Sep | D31: 10 | E31: 0 | F31: 10534.87 | G31: Tier 2 | H31: Tier 2 | I31: ZN2005
A32: PT00389 | B32: 1992 | C32: Oct | D32: 9 | E32: 0 | F32: 4323.94 | G32: Tier 1 | H32: Tier 3 | I32: ZN2002
A33: PT02163 | B33: 2019 | C33: Feb | D33: 10 | E33: 1 | F33: 3221.35 | G33: Tier 1 | H33: Tier 2 | I33: ZN2017
A34: PT00748 | B34: 2010 | C34: Jun | D34: 4 | E34: 2 | F34: 15372.31 | G34: Tier 2 | H34: Tier 2 | I34: ZN2015
A35: PT01781 | B35: 2008 | C35: Aug | D35: 5 | E35: 0 | F35: 8590.13 | G35: Tier 2 | H35: Tier 2 | I35: ZN2010
A36: PT01788 | B36: 1987 | C36: Jul | D36: 28 | E36: 2 | F36: 10529.65 | G36: Tier 3 | H36: Tier 3 | I36: ZN2016
A37: PT01285 | B37: 2002 | C37: Dec | D37: 20 | E37: 2 | F37: 7480.08 | G37: Tier 1 | H37: Tier 3 | I37: ZN2014
A38: PT00282 | B38: 2002 | C38: Dec | D38: 19 | E38: 0 | F38: 3456.26 | G38: Tier 2 | H38: Tier 3 | I38: ZN2004
A39: PT00654 | B39: 1995 | C39: Oct | D39: 8 | E39: 0 | F39: 10737.13 | G39: Tier 2 | H39: Tier 2 | I39: ZN2008
A40: PT01429 | B40: 2007 | C40: Mar | D40: 24 | E40: 0 | F40: 6322.37 | G40: Tier 3 | H40: Tier 1 | I40: ZN2018
... A51: PT01079 | B51: 2023 | C51: Apr | D51: 13 | E51: 0 | F51: 13264.11 | G51: Tier 1 | H51: Tier 2 | I51: ZN2014
A52: PT00379 | B52: ? | C52: ? | D52: 10 | E52: 0 | F52: 2835.03 | G52: Tier 2 | H52: Tier 2 | I52: ZN2009
A53: PT00550 | B53: 2006 | C53: Mar | D53: 12 | E53: 1 | F53: 14429.82 | G53: Tier 3 | H53: Tier 2 | I53: ZN2010
A54: PT01901 | B54: 2015 | C54: Feb | D54: 25 | E54: 1 | F54: 7099.15 | G54: Tier 2 | H54: Tier 3 | I54: ZN2015
A55: PT02238 | B55: 2004 | C55: Apr | D55: 11 | E55: 0 | F55: 8071.09 | G55: Tier 2 | H55: Tier 1 | I55: ZN2015
A56: PT00144 | B56: 2008 | C56: Feb | D56: 28 | E56: 1 | F56: 7102.66 | G56: Tier 2 | H56: Tier 2 | I56: ZN2018
A57: PT01580 | B57: 2020 | C57: Aug | D57: 5 | E57: 0 | F57: 20734.53 | G57: Tier 3 | H57: Tier 3 | I57: ZN2004
A58: PT01126 | B58: 1988 | C58: Sep | D58: 5 | E58: 4 | F58: 18161.91 | G58: Tier 2 | H58: Tier 2 | I58: ZN2009
A59: PT00603 | B59: 1998 | C59: Jan | D59: 10 | E59: 0 | F59: 7174.81 | G59: ? | H59: Tier 2 | I59: ZN2002
A60: PT01195 | B60: 1989 | C60: Feb | D60: 1 | E60: 1 | F60: 3735.91 | G60: Tier 1 | H60: Tier 1 | I60: ZN2006
A61: PT02186 | B61: 2016 | C61: Jun | D61: 25 | E61: 0 | F61: 14660.57 | G61: ? | H61: Tier 2 | I61: ZN2011
A62: PT00462 | B62: 2017 | C62: Feb | D62: 10 | E62: 0 | F62: 3530.06 | G62: Tier 2 | H62: Tier 1 | I62: ZN2003
A63: PT01955 | B63: 2013 | C63: Oct | D63: 3 | E63: 1 | F63: 2284.39 | G63: Tier 3 | H63: Tier 2 | I63: ZN2009
...

Sheet Admission Records (2)
A1: Patient ID | B1: Admission Year | C1: Admission Month | D1: Admission Day | E1: Admission Date | F1: Dependents | G1: Billed Amount | H1: Facility Tier | I1: City Tier | J1: Region Code
A2: PT01684 | B2: 1995 | C2: Jul | D2: 15 | E2: =_xlfn.CONCAT(Admission_Records[[#This Row],[Admission Day]],Admission_Records[[#This Row],[Admission Month]],Admission_Records[[#This Row],[Admission Year]]) -> 15Jul1995 | F2: 0 | G2: 2652.98 | H2: Tier 2 | I2: Tier 2 | J2: ZN2015
A3: PT01854 | B3: 1998 | C3: Sep | D3: 20 | E3: =_xlfn.CONCAT(Admission_Records[[#This Row],[Admission Day]],Admission_Records[[#This Row],[Admission Month]],Admission_Records[[#This Row],[Admission Year]]) -> 20Sep1998 | F3: 0 | G3: 2553.18 | H3: Tier 2 | I3: Tier 2 | J3: ZN2011
A4: PT01397 | B4: 2001 | C4: Sep | D4: 10 | E4: =_xlfn.CONCAT(Admission_Records[[#This Row],[Admission Day]],Admission_Records[[#This Row],[Admission Month]],Admission_Records[[#This Row],[Admission Year]]) -> 10Sep2001 | F4: 0 | G4: 10534.87 | H4: Tier 2 | I4: Tier 2 | J4: ZN2005
A5: PT01781 | B5: 2008 | C5: Aug | D5: 5 | E5: =_xlfn.CONCAT(Admission_Records[[#This Row],[Admission Day]],Admission_Records[[#This Row],[Admission Month]],Admission_Records[[#This Row],[Admission Year]]) -> 5Aug2008 | F5: 0 | G5: 8590.13 | H5: Tier 2 | I5: Tier 2 | J5: ZN2010
A6: PT00654 | B6: 1995 | C6: Oct | D6: 8 | E6: =_xlfn.CONCAT(Admission_Records[[#This Row],[Admission Day]],Admission_Records[[#This Row],[Admission Month]],Admission_Records[[#This Row],[Admission Year]]) -> 8Oct1995 | F6: 0 | G6: 10737.13 | H6: Tier 2 | I6: Tier 2 | J6: ZN2008
A7: PT01257 | B7: 2013 | C7: Sep | D7: 10 | E7: =_xlfn.CONCAT(Admission_Records[[#This Row],[Admission Day]],Admission_Records[[#This Row],[Admission Month]],Admission_Records[[#This Row],[Admission Year]]) -> 10Sep2013 | F7: 0 | G7: 14692.22 | H7: Tier 2 | I7: Tier 2 | J7: ZN2011
A8: PT01131 | B8: 1993 | C8: Feb | D8: 12 | E8: =_xlfn.CONCAT(Admission_Records[[#This Row],[Admission Day]],Admission_Records[[#This Row],[Admission Month]],Admission_Records[[#This Row],[Admission Year]]) -> 12Feb1993 | F8: 0 | G8: 9783.28 | H8: Tier 2 | I8: Tier 2 | J8: ZN2013
A9: PT00379 | B9: 2003 | C9: Sep | D9: 10 | E9: =_xlfn.CONCAT(Admission_Records[[#This Row],[Admission Day]],Admission_Records[[#This Row],[Admission Month]],Admission_Records[[#This Row],[Admission Year]]) -> 10Sep2003 | F9: 0 | G9: 2835.03 | H9: Tier 2 | I9: Tier 2 | J9: ZN2009
A10: PT00603 | B10: 1998 | C10: Jan | D10: 10 | E10: =_xlfn.CONCAT(Admission_Records[[#This Row],[Admission Day]],Admission_Records[[#This Row],[Admission Month]],Admission_Records[[#This Row],[Admission Year]]) -> 10Jan1998 | F10: 0 | G10: 7174.81 | H10: Tier 2 | I10: Tier 2 | J10: ZN2002
A11: PT02186 | B11: 2016 | C11: Jun | D11: 25 | E11: =_xlfn.CONCAT(Admission_Records[[#This Row],[Admission Day]],Admission_Records[[#This Row],[Admission Month]],Admission_Records[[#This Row],[Admission Year]]) -> 25Jun2016 | F11: 0 | G11: 14660.57 | H11: Tier 2 | I11: Tier 2 | J11: ZN2011
A12: PT01880 | B12: 2022 | C12: Oct | D12: 11 | E12: =_xlfn.CONCAT(Admission_Records[[#This Row],[Admission Day]],Admission_Records[[#This Row],[Admission Month]],Admission_Records[[#This Row],[Admission Year]]) -> 11Oct2022 | F12: 0 | G12: 12600.54 | H12: Tier 2 | I12: Tier 2 | J12: ZN2014
A13: PT01141 | B13: 2017 | C13: Feb | D13: 5 | E13: =_xlfn.CONCAT(Admission_Records[[#This Row],[Admission Day]],Admission_Records[[#This Row],[Admission Month]],Admission_Records[[#This Row],[Admission Year]]) -> 5Feb2017 | F13: 0 | G13: 3126.21 | H13: Tier 2 | I13: Tier 2 | J13: ZN2014
... A2344: PT01684 | B2344: 1988 | C2344: Nov | D2344: 19 | E2344: =_xlfn.CONCAT(Admission_Records[[#This Row],[Admission Day]],Admission_Records[[#This Row],[Admission Month]],Admission_Records[[#This Row],[Admission Year]]) -> 19Nov1988 | F2344: 5 | G2344: 6571.03 | H2344: Tier 2 | I2344: Tier 2 | J2344: ZN2004

Sheet Clinical Assessments (2)
A1: Patient ID | B1: BMI | C1: HbA1c Level | D1: Cardiac Condition | E1: Organ Transplant History | F1: Cancer History | G1: Major Surgeries Count | H1: Tobacco Use
A2: PT00048 | B2: 31.02 | C2: 4 | D2: No | E2: No | F2: No | G2: 0 | H2: No
A3: PT00061 | B3: 18.06 | C3: 4 | D3: No | E3: No | F3: No | G3: 0 | H3: No
A4: PT00079 | B4: 33.75 | C4: 4 | D4: No | E4: No | F4: No | G4: 0 | H4: No
A5: PT00086 | B5: 32.81 | C5: 4 | D5: No | E5: No | F5: No | G5: 0 | H5: No
A6: PT00185 | B6: 32.42 | C6: 4 | D6: No | E6: No | F6: No | G6: 0 | H6: No
A7: PT00203 | B7: 30.12 | C7: 4 | D7: No | E7: No | F7: No | G7: 0 | H7: No
A8: PT00214 | B8: 26.21 | C8: 4 | D8: No | E8: No | F8: No | G8: 0 | H8: No
A9: PT00260 | B9: 20.15 | C9: 4 | D9: No | E9: No | F9: No | G9: 0 | H9: No
A10: PT00275 | B10: 40.2 | C10: 4 | D10: No | E10: No | F10: No | G10: 0 | H10: No
A11: PT00280 | B11: 31.29 | C11: 4 | D11: No | E11: No | F11: No | G11: 0 | H11: No
A12: PT00317 | B12: 29.95 | C12: 4 | D12: No | E12: No | F12: No | G12: 0 | H12: No
A13: PT00352 | B13: 35.26 | C13: 4 | D13: No | E13: No | F13: No | G13: 0 | H13: No
... A2336: PT02330 | B2336: 36.3 | C2336: 10.99 | D2336: No | E2336: No | F2336: No | G2336: 0 | H2336: No

Sheet Patient Directory (2)
A1: Patient ID | B1: Full Name | C1: Last Name
A2: PT00001 | B2: Allison Hill | C2: Hill
A3: PT00002 | B3: Noah Rhodes | C3: Rhodes
A4: PT00003 | B4: Angie Henderson | C4: Henderson
A5: PT00004 | B5: Daniel Wagner | C5: Wagner
A6: PT00005 | B6: Cristian Santos | C6: Santos
A7: PT00006 | B7: Connie Lawrence | C7: Lawrence
A8: PT00007 | B8: Abigail Shaffer | C8: Shaffer
A9: PT00008 | B9: Gina Moore | C9: Moore
A10: PT00009 | B10: Gabrielle Davis | C10: Davis
A11: PT00010 | B11: Ryan Munoz | C11: Munoz
A12: PT00011 | B12: Monica Herrera | C12: Herrera
... A2336: PT02335 | B2336: Scott Stewart | C2336: Stewart

Sheet Patient Insights
A1: Patient ID | B1: First Name | C1: BMI | D1: HbA1c Level | E1: Cardiac Condition | F1: Organ Transplant History | G1: Cancer history | H1: Major Surgeries Count | I1: Tobacco Use | J1: Weight Status | K1: Diabetes Status | L1: Admission Date | M1: Billed Amount | N1: Facility Tier | O1: City Teir | P1: Region Code
A2: PT00001 | B2: =VLOOKUP(A2,'Patient Directory (2)'!$A:$B,2,FALSE) -> Allison Hill | C2: =VLOOKUP(A2,'Clinical Assessments (2)'!$A:$B,2,FALSE) -> 31.57 | D2: =VLOOKUP(A2,'Clinical Assessments (2)'!$A:$C,3,FALSE) -> 6.36 | E2: =VLOOKUP(A2,'Clinical Assessments (2)'!$A:$D,4,FALSE) -> No | F2: =VLOOKUP(A2,'Clinical Assessments (2)'!$A:$E,5,FALSE) -> No | G2: =VLOOKUP(A2,'Clinical Assessments (2)'!$A:$F,6,FALSE) -> No | H2: =VLOOKUP(A2,'Clinical Assessments (2)'!$A:$G,7,FALSE) -> 1 | I2: =VLOOKUP(A2,'Clinical Assessments (2)'!$A:$H,8,FALSE) -> No | J2: =IF(C2<18.5,"Under weight",IF(C2<25,"Normal weight",IF(C2<30,"Over weight","Obesity"))) -> Obesity | K2: =IF('Patient Insights'!D2<5.7,"Normal",IF('Patient Insights'!D2<6.5,"Prediabetes","Diabetes")) -> Prediabetes | L2: =IFERROR(VLOOKUP(A2,'Admission Records (2)'!$A:$E,5,FALSE),"Unknown") -> Unknown | M2: =IFERROR(VLOOKUP(A2,'Admission Records (2)'!$A:$G,7,FALSE),"Unknown") -> Unknown | N2: =IFERROR(VLOOKUP(A2,'Admission Records (2)'!$A:$H,8,FALSE),"Unknown") -> Unknown | O2: =IFERROR(VLOOKUP(A2,'Admission Records (2)'!$A:$I,9,FALSE),"Unknown") -> Unknown | P2: =IFERROR(VLOOKUP(A2,'Admission Records (2)'!$A:$J,10,FALSE),"Unknown") -> Unknown
A3: PT00002 | B3: =VLOOKUP(A3,'Patient Directory (2)'!$A:$B,2,FALSE) -> Noah Rhodes | C3: =VLOOKUP(A3,'Clinical Assessments (2)'!$A:$B,2,FALSE) -> 22.43 | D3: =VLOOKUP(A3,'Clinical Assessments (2)'!$A:$C,3,FALSE) -> 11.46 | E3: =VLOOKUP(A3,'Clinical Assessments (2)'!$A:$D,4,FALSE) -> No | F3: =VLOOKUP(A3,'Clinical Assessments (2)'!$A:$E,5,FALSE) -> No | G3: =VLOOKUP(A3,'Clinical Assessments (2)'!$A:$F,6,FALSE) -> No | H3: =VLOOKUP(A3,'Clinical Assessments (2)'!$A:$G,7,FALSE) -> 0 | I3: =VLOOKUP(A3,'Clinical Assessments (2)'!$A:$H,8,FALSE) -> Yes | J3: =IF(C3<18.5,"Under weight",IF(C3<25,"Normal weight",IF(C3<30,"Over weight","Obesity"))) -> Normal weight | K3: =IF('Patient Insights'!D3<5.7,"Normal",IF('Patient Insights'!D3<6.5,"Prediabetes","Diabetes")) -> Diabetes | L3: =IFERROR(VLOOKUP(A3,'Admission Records (2)'!$A:$E,5,FALSE),"Unknown") -> 13Jul1992 | M3: =IFERROR(VLOOKUP(A3,'Admission Records (2)'!$A:$G,7,FALSE),"Unknown") -> 4072.08 | N3: =IFERROR(VLOOKUP(A3,'Admission Records (2)'!$A:$H,8,FALSE),"Unknown") -> Tier 3 | O3: =IFERROR(VLOOKUP(A3,'Admission Records (2)'!$A:$I,9,FALSE),"Unknown") -> Tier 1 | P3: =IFERROR(VLOOKUP(A3,'Admission Records (2)'!$A:$J,10,FALSE),"Unknown") -> ZN2004
A4: PT00003 | B4: =VLOOKUP(A4,'Patient Directory (2)'!$A:$B,2,FALSE) -> Angie Henderson | C4: =VLOOKUP(A4,'Clinical Assessments (2)'!$A:$B,2,FALSE) -> 34.6 | D4: =VLOOKUP(A4,'Clinical Assessments (2)'!$A:$C,3,FALSE) -> 7.79 | E4: =VLOOKUP(A4,'Clinical Assessments (2)'!$A:$D,4,FALSE) -> No | F4: =VLOOKUP(A4,'Clinical Assessments (2)'!$A:$E,5,FALSE) -> No | G4: =VLOOKUP(A4,'Clinical Assessments (2)'!$A:$F,6,FALSE) -> Yes | H4: =VLOOKUP(A4,'Clinical Assessments (2)'!$A:$G,7,FALSE) -> 1 | I4: =VLOOKUP(A4,'Clinical Assessments (2)'!$A:$H,8,FALSE) -> No | J4: =IF(C4<18.5,"Under weight",IF(C4<25,"Normal weight",IF(C4<30,"Over weight","Obesity"))) -> Obesity | K4: =IF('Patient Insights'!D4<5.7,"Normal",IF('Patient Insights'!D4<6.5,"Prediabetes","Diabetes")) -> Diabetes | L4: =IFERROR(VLOOKUP(A4,'Admission Records (2)'!$A:$E,5,FALSE),"Unknown") -> 18Jun1999 | M4: =IFERROR(VLOOKUP(A4,'Admission Records (2)'!$A:$G,7,FALSE),"Unknown") -> 15384.24 | N4: =IFERROR(VLOOKUP(A4,'Admission Records (2)'!$A:$H,8,FALSE),"Unknown") -> Tier 2 | O4: =IFERROR(VLOOKUP(A4,'Admission Records (2)'!$A:$I,9,FALSE),"Unknown") -> Tier 1 | P4: =IFERROR(VLOOKUP(A4,'Admission Records (2)'!$A:$J,10,FALSE),"Unknown") -> ZN2001
A5: PT00004 | B5: =VLOOKUP(A5,'Patient Directory (2)'!$A:$B,2,FALSE) -> Daniel Wagner | C5: =VLOOKUP(A5,'Clinical Assessments (2)'!$A:$B,2,FALSE) -> 35.9 | D5: =VLOOKUP(A5,'Clinical Assessments (2)'!$A:$C,3,FALSE) -> 8.19 | E5: =VLOOKUP(A5,'Clinical Assessments (2)'!$A:$D,4,FALSE) -> No | F5: =VLOOKUP(A5,'Clinical Assessments (2)'!$A:$E,5,FALSE) -> Yes | G5: =VLOOKUP(A5,'Clinical Assessments (2)'!$A:$F,6,FALSE) -> No | H5: =VLOOKUP(A5,'Clinical Assessments (2)'!$A:$G,7,FALSE) -> 1 | I5: =VLOOKUP(A5,'Clinical Assessments (2)'!$A:$H,8,FALSE) -> Yes | J5: =IF(C5<18.5,"Under weight",IF(C5<25,"Normal weight",IF(C5<30,"Over weight","Obesity"))) -> Obesity | K5: =IF('Patient Insights'!D5<5.7,"Normal",IF('Patient Insights'!D5<6.5,"Prediabetes","Diabetes")) -> Diabetes | L5: =IFERROR(VLOOKUP(A5,'Admission Records (2)'!$A:$E,5,FALSE),"Unknown") -> 2Sep2019 | M5: =IFERROR(VLOOKUP(A5,'Admission Records (2)'!$A:$G,7,FALSE),"Unknown") -> 14474.39 | N5: =IFERROR(VLOOKUP(A5,'Admission Records (2)'!$A:$H,8,FALSE),"Unknown") -> Tier 2 | O5: =IFERROR(VLOOKUP(A5,'Admission Records (2)'!$A:$I,9,FALSE),"Unknown") -> Tier 1 | P5: =IFERROR(VLOOKUP(A5,'Admission Records (2)'!$A:$J,10,FALSE),"Unknown") -> ZN2015
A6: PT00005 | B6: =VLOOKUP(A6,'Patient Directory (2)'!$A:$B,2,FALSE) -> Cristian Santos | C6: =VLOOKUP(A6,'Clinical Assessments (2)'!$A:$B,2,FALSE) -> 16.23 | D6: =VLOOKUP(A6,'Clinical Assessments (2)'!$A:$C,3,FALSE) -> 7.8 | E6: =VLOOKUP(A6,'Clinical Assessments (2)'!$A:$D,4,FALSE) -> No | F6: =VLOOKUP(A6,'Clinical Assessments (2)'!$A:$E,5,FALSE) -> No | G6: =VLOOKUP(A6,'Clinical Assessments (2)'!$A:$F,6,FALSE) -> No | H6: =VLOOKUP(A6,'Clinical Assessments (2)'!$A:$G,7,FALSE) -> 1 | I6: =VLOOKUP(A6,'Clinical Assessments (2)'!$A:$H,8,FALSE) -> Yes | J6: =IF(C6<18.5,"Under weight",IF(C6<25,"Normal weight",IF(C6<30,"Over weight","Obesity"))) -> Under weight | K6: =IF('Patient Insights'!D6<5.7,"Normal",IF('Patient Insights'!D6<6.5,"Prediabetes","Diabetes")) -> Diabetes | L6: =IFERROR(VLOOKUP(A6,'Admission Records (2)'!$A:$E,5,FALSE),"Unknown") -> Unknown | M6: =IFERROR(VLOOKUP(A6,'Admission Records (2)'!$A:$G,7,FALSE),"Unknown") -> Unknown | N6: =IFERROR(VLOOKUP(A6,'Admission Records (2)'!$A:$H,8,FALSE),"Unknown") -> Unknown | O6: =IFERROR(VLOOKUP(A6,'Admission Records (2)'!$A:$I,9,FALSE),"Unknown") -> Unknown | P6: =IFERROR(VLOOKUP(A6,'Admission Records (2)'!$A:$J,10,FALSE),"Unknown") -> Unknown
A7: PT00006 | B7: =VLOOKUP(A7,'Patient Directory (2)'!$A:$B,2,FALSE) -> Connie Lawrence | C7: =VLOOKUP(A7,'Clinical Assessments (2)'!$A:$B,2,FALSE) -> 20.65 | D7: =VLOOKUP(A7,'Clinical Assessments (2)'!$A:$C,3,FALSE) -> 9.01 | E7: =VLOOKUP(A7,'Clinical Assessments (2)'!$A:$D,4,FALSE) -> No | F7: =VLOOKUP(A7,'Clinical Assessments (2)'!$A:$E,5,FALSE) -> No | G7: =VLOOKUP(A7,'Clinical Assessments (2)'!$A:$F,6,FALSE) -> No | H7: =VLOOKUP(A7,'Clinical Assessments (2)'!$A:$G,7,FALSE) -> 0 | I7: =VLOOKUP(A7,'Clinical Assessments (2)'!$A:$H,8,FALSE) -> Yes | J7: =IF(C7<18.5,"Under weight",IF(C7<25,"Normal weight",IF(C7<30,"Over weight","Obesity"))) -> Normal weight | K7: =IF('Patient Insights'!D7<5.7,"Normal",IF('Patient Insights'!D7<6.5,"Prediabetes","Diabetes")) -> Diabetes | L7: =IFERROR(VLOOKUP(A7,'Admission Records (2)'!$A:$E,5,FALSE),"Unknown") -> 17Nov1995 | M7: =IFERROR(VLOOKUP(A7,'Admission Records (2)'!$A:$G,7,FALSE),"Unknown") -> 22904.73 | N7: =IFERROR(VLOOKUP(A7,'Admission Records (2)'!$A:$H,8,FALSE),"Unknown") -> Tier 1 | O7: =IFERROR(VLOOKUP(A7,'Admission Records (2)'!$A:$I,9,FALSE),"Unknown") -> Tier 2 | P7: =IFERROR(VLOOKUP(A7,'Admission Records (2)'!$A:$J,10,FALSE),"Unknown") -> ZN2016
A8: PT00007 | B8: =VLOOKUP(A8,'Patient Directory (2)'!$A:$B,2,FALSE) -> Abigail Shaffer | C8: =VLOOKUP(A8,'Clinical Assessments (2)'!$A:$B,2,FALSE) -> 30.37 | D8: =VLOOKUP(A8,'Clinical Assessments (2)'!$A:$C,3,FALSE) -> 5.84 | E8: =VLOOKUP(A8,'Clinical Assessments (2)'!$A:$D,4,FALSE) -> Yes | F8: =VLOOKUP(A8,'Clinical Assessments (2)'!$A:$E,5,FALSE) -> No | G8: =VLOOKUP(A8,'Clinical Assessments (2)'!$A:$F,6,FALSE) -> No | H8: =VLOOKUP(A8,'Clinical Assessments (2)'!$A:$G,7,FALSE) -> 0 | I8: =VLOOKUP(A8,'Clinical Assessments (2)'!$A:$H,8,FALSE) -> No | J8: =IF(C8<18.5,"Under weight",IF(C8<25,"Normal weight",IF(C8<30,"Over weight","Obesity"))) -> Obesity | K8: =IF('Patient Insights'!D8<5.7,"Normal",IF('Patient Insights'!D8<6.5,"Prediabetes","Diabetes")) -> Prediabetes | L8: =IFERROR(VLOOKUP(A8,'Admission Records (2)'!$A:$E,5,FALSE),"Unknown") -> 11May1986 | M8: =IFERROR(VLOOKUP(A8,'Admission Records (2)'!$A:$G,7,FALSE),"Unknown") -> 7811.68 | N8: =IFERROR(VLOOKUP(A8,'Admission Records (2)'!$A:$H,8,FALSE),"Unknown") -> Tier 1 | O8: =IFERROR(VLOOKUP(A8,'Admission Records (2)'!$A:$I,9,FALSE),"Unknown") -> Tier 3 | P8: =IFERROR(VLOOKUP(A8,'Admission Records (2)'!$A:$J,10,FALSE),"Unknown") -> ZN2016
A9: PT00008 | B9: =VLOOKUP(A9,'Patient Directory (2)'!$A:$B,2,FALSE) -> Gina Moore | C9: =VLOOKUP(A9,'Clinical Assessments (2)'!$A:$B,2,FALSE) -> 27.35 | D9: =VLOOKUP(A9,'Clinical Assessments (2)'!$A:$C,3,FALSE) -> 4 | E9: =VLOOKUP(A9,'Clinical Assessments (2)'!$A:$D,4,FALSE) -> No | F9: =VLOOKUP(A9,'Clinical Assessments (2)'!$A:$E,5,FALSE) -> No | G9: =VLOOKUP(A9,'Clinical Assessments (2)'!$A:$F,6,FALSE) -> Yes | H9: =VLOOKUP(A9,'Clinical Assessments (2)'!$A:$G,7,FALSE) -> 0 | I9: =VLOOKUP(A9,'Clinical Assessments (2)'!$A:$H,8,FALSE) -> No | J9: =IF(C9<18.5,"Under weight",IF(C9<25,"Normal weight",IF(C9<30,"Over weight","Obesity"))) -> Over weight | K9: =IF('Patient Insights'!D9<5.7,"Normal",IF('Patient Insights'!D9<6.5,"Prediabetes","Diabetes")) -> Normal | L9: =IFERROR(VLOOKUP(A9,'Admission Records (2)'!$A:$E,5,FALSE),"Unknown") -> 22Jan2021 | M9: =IFERROR(VLOOKUP(A9,'Admission Records (2)'!$A:$G,7,FALSE),"Unknown") -> 2241.58 | N9: =IFERROR(VLOOKUP(A9,'Admission Records (2)'!$A:$H,8,FALSE),"Unknown") -> Tier 1 | O9: =IFERROR(VLOOKUP(A9,'Admission Records (2)'!$A:$I,9,FALSE),"Unknown") -> Tier 2 | P9: =IFERROR(VLOOKUP(A9,'Admission Records (2)'!$A:$J,10,FALSE),"Unknown") -> ZN2012
A10: PT00009 | B10: =VLOOKUP(A10,'Patient Directory (2)'!$A:$B,2,FALSE) -> Gabrielle Davis | C10: =VLOOKUP(A10,'Clinical Assessments (2)'!$A:$B,2,FALSE) -> 29.39 | D10: =VLOOKUP(A10,'Clinical Assessments (2)'!$A:$C,3,FALSE) -> 5.84 | E10: =VLOOKUP(A10,'Clinical Assessments (2)'!$A:$D,4,FALSE) -> No | F10: =VLOOKUP(A10,'Clinical Assessments (2)'!$A:$E,5,FALSE) -> No | G10: =VLOOKUP(A10,'Clinical Assessments (2)'!$A:$F,6,FALSE) -> No | H10: =VLOOKUP(A10,'Clinical Assessments (2)'!$A:$G,7,FALSE) -> 2 | I10: =VLOOKUP(A10,'Clinical Assessments (2)'!$A:$H,8,FALSE) -> No | J10: =IF(C10<18.5,"Under weight",IF(C10<25,"Normal weight",IF(C10<30,"Over weight","Obesity"))) -> Over weight | K10: =IF('Patient Insights'!D10<5.7,"Normal",IF('Patient Insights'!D10<6.5,"Prediabetes","Diabetes")) -> Prediabetes | L10: =IFERROR(VLOOKUP(A10,'Admission Records (2)'!$A:$E,5,FALSE),"Unknown") -> 5Mar1986 | M10: =IFERROR(VLOOKUP(A10,'Admission Records (2)'!$A:$G,7,FALSE),"Unknown") -> 8934.14 | N10: =IFERROR(VLOOKUP(A10,'Admission Records (2)'!$A:$H,8,FALSE),"Unknown") -> Tier 2 | O10: =IFERROR(VLOOKUP(A10,'Admission Records (2)'!$A:$I,9,FALSE),"Unknown") -> Tier 1 | P10: =IFERROR(VLOOKUP(A10,'Admission Records (2)'!$A:$J,10,FALSE),"Unknown") -> ZN2008
A11: PT00010 | B11: =VLOOKUP(A11,'Patient Directory (2)'!$A:$B,2,FALSE) -> Ryan Munoz | C11: =VLOOKUP(A11,'Clinical Assessments (2)'!$A:$B,2,FALSE) -> 23.7 | D11: =VLOOKUP(A11,'Clinical Assessments (2)'!$A:$C,3,FALSE) -> 7.74 | E11: =VLOOKUP(A11,'Clinical Assessments (2)'!$A:$D,4,FALSE) -> No | F11: =VLOOKUP(A11,'Clinical Assessments (2)'!$A:$E,5,FALSE) -> No | G11: =VLOOKUP(A11,'Clinical Assessments (2)'!$A:$F,6,FALSE) -> No | H11: =VLOOKUP(A11,'Clinical Assessments (2)'!$A:$G,7,FALSE) -> 0 | I11: =VLOOKUP(A11,'Clinical Assessments (2)'!$A:$H,8,FALSE) -> No | J11: =IF(C11<18.5,"Under weight",IF(C11<25,"Normal weight",IF(C11<30,"Over weight","Obesity"))) -> Normal weight | K11: =IF('Patient Insights'!D11<5.7,"Normal",IF('Patient Insights'!D11<6.5,"Prediabetes","Diabetes")) -> Diabetes | L11: =IFERROR(VLOOKUP(A11,'Admission Records (2)'!$A:$E,5,FALSE),"Unknown") -> 1Aug1995 | M11: =IFERROR(VLOOKUP(A11,'Admission Records (2)'!$A:$G,7,FALSE),"Unknown") -> 7121.61 | N11: =IFERROR(VLOOKUP(A11,'Admission Records (2)'!$A:$H,8,FALSE),"Unknown") -> Tier 2 | O11: =IFERROR(VLOOKUP(A11,'Admission Records (2)'!$A:$I,9,FALSE),"Unknown") -> Tier 1 | P11: =IFERROR(VLOOKUP(A11,'Admission Records (2)'!$A:$J,10,FALSE),"Unknown") -> ZN2010
A12: PT00011 | B12: =VLOOKUP(A12,'Patient Directory (2)'!$A:$B,2,FALSE) -> Monica Herrera | C12: =VLOOKUP(A12,'Clinical Assessments (2)'!$A:$B,2,FALSE) -> 35.48 | D12: =VLOOKUP(A12,'Clinical Assessments (2)'!$A:$C,3,FALSE) -> 4.36 | E12: =VLOOKUP(A12,'Clinical Assessments (2)'!$A:$D,4,FALSE) -> No | F12: =VLOOKUP(A12,'Clinical Assessments (2)'!$A:$E,5,FALSE) -> No | G12: =VLOOKUP(A12,'Clinical Assessments (2)'!$A:$F,6,FALSE) -> No | H12: =VLOOKUP(A12,'Clinical Assessments (2)'!$A:$G,7,FALSE) -> 1 | I12: =VLOOKUP(A12,'Clinical Assessments (2)'!$A:$H,8,FALSE) -> Yes | J12: =IF(C12<18.5,"Under weight",IF(C12<25,"Normal weight",IF(C12<30,"Over weight","Obesity"))) -> Obesity | K12: =IF('Patient Insights'!D12<5.7,"Normal",IF('Patient Insights'!D12<6.5,"Prediabetes","Diabetes")) -> Normal | L12: =IFERROR(VLOOKUP(A12,'Admission Records (2)'!$A:$E,5,FALSE),"Unknown") -> 22Apr1997 | M12: =IFERROR(VLOOKUP(A12,'Admission Records (2)'!$A:$G,7,FALSE),"Unknown") -> 13958.72 | N12: =IFERROR(VLOOKUP(A12,'Admission Records (2)'!$A:$H,8,FALSE),"Unknown") -> Tier 3 | O12: =IFERROR(VLOOKUP(A12,'Admission Records (2)'!$A:$I,9,FALSE),"Unknown") -> Tier 1 | P12: =IFERROR(VLOOKUP(A12,'Admission Records (2)'!$A:$J,10,FALSE),"Unknown") -> ZN2015
A13: PT00012 | B13: =VLOOKUP(A13,'Patient Directory (2)'!$A:$B,2,FALSE) -> Jamie Arnold | C13: =VLOOKUP(A13,'Clinical Assessments (2)'!$A:$B,2,FALSE) -> 34.79 | D13: =VLOOKUP(A13,'Clinical Assessments (2)'!$A:$C,3,FALSE) -> 5.86 | E13: =VLOOKUP(A13,'Clinical Assessments (2)'!$A:$D,4,FALSE) -> No | F13: =VLOOKUP(A13,'Clinical Assessments (2)'!$A:$E,5,FALSE) -> No | G13: =VLOOKUP(A13,'Clinical Assessments (2)'!$A:$F,6,FALSE) -> No | H13: =VLOOKUP(A13,'Clinical Assessments (2)'!$A:$G,7,FALSE) -> 1 | I13: =VLOOKUP(A13,'Clinical Assessments (2)'!$A:$H,8,FALSE) -> No | J13: =IF(C13<18.5,"Under weight",IF(C13<25,"Normal weight",IF(C13<30,"Over weight","Obesity"))) -> Obesity | K13: =IF('Patient Insights'!D13<5.7,"Normal",IF('Patient Insights'!D13<6.5,"Prediabetes","Diabetes")) -> Prediabetes | L13: =IFERROR(VLOOKUP(A13,'Admission Records (2)'!$A:$E,5,FALSE),"Unknown") -> Unknown | M13: =IFERROR(VLOOKUP(A13,'Admission Records (2)'!$A:$G,7,FALSE),"Unknown") -> Unknown | N13: =IFERROR(VLOOKUP(A13,'Admission Records (2)'!$A:$H,8,FALSE),"Unknown") -> Unknown | O13: =IFERROR(VLOOKUP(A13,'Admission Records (2)'!$A:$I,9,FALSE),"Unknown") -> Unknown | P13: =IFERROR(VLOOKUP(A13,'Admission Records (2)'!$A:$J,10,FALSE),"Unknown") -> Unknown
... A1337: PT01336 | B1337: =VLOOKUP(A1337,'Patient Directory (2)'!$A:$B,2,FALSE) -> Vincent Smith | C1337: =VLOOKUP(A1337,'Clinical Assessments (2)'!$A:$B,2,FALSE) -> 42.14 | D1337: =VLOOKUP(A1337,'Clinical Assessments (2)'!$A:$C,3,FALSE) -> 7.13 | E1337: =VLOOKUP(A1337,'Clinical Assessments (2)'!$A:$D,4,FALSE) -> No | F1337: =VLOOKUP(A1337,'Clinical Assessments (2)'!$A:$E,5,FALSE) -> No | G1337: =VLOOKUP(A1337,'Clinical Assessments (2)'!$A:$F,6,FALSE) -> No | H1337: =VLOOKUP(A1337,'Clinical Assessments (2)'!$A:$G,7,FALSE) -> 1 | I1337: =VLOOKUP(A1337,'Clinical Assessments (2)'!$A:$H,8,FALSE) -> No | J1337: =IF(C1337<18.5,"Under weight",IF(C1337<25,"Normal weight",IF(C1337<30,"Over weight","Obesity"))) -> Obesity | K1337: =IF('Patient Insights'!D1337<5.7,"Normal",IF('Patient Insights'!D1337<6.5,"Prediabetes","Diabetes")) -> Diabetes | L1337: =IFERROR(VLOOKUP(A1337,'Admission Records (2)'!$A:$E,5,FALSE),"Unknown") -> Unknown | M1337: =IFERROR(VLOOKUP(A1337,'Admission Records (2)'!$A:$G,7,FALSE),"Unknown") -> Unknown | N1337: =IFERROR(VLOOKUP(A1337,'Admission Records (2)'!$A:$H,8,FALSE),"Unknown") -> Unknown | O1337: =IFERROR(VLOOKUP(A1337,'Admission Records (2)'!$A:$I,9,FALSE),"Unknown") -> Unknown | P1337: =IFERROR(VLOOKUP(A1337,'Admission Records (2)'!$A:$J,10,FALSE),"Unknown") -> Unknown
A1338: PT01337 | B1338: =VLOOKUP(A1338,'Patient Directory (2)'!$A:$B,2,FALSE) -> Charles Frost | C1338: =VLOOKUP(A1338,'Clinical Assessments (2)'!$A:$B,2,FALSE) -> 32.69 | D1338: =VLOOKUP(A1338,'Clinical Assessments (2)'!$A:$C,3,FALSE) -> 7.2 | E1338: =VLOOKUP(A1338,'Clinical Assessments (2)'!$A:$D,4,FALSE) -> No | F1338: =VLOOKUP(A1338,'Clinical Assessments (2)'!$A:$E,5,FALSE) -> No | G1338: =VLOOKUP(A1338,'Clinical Assessments (2)'!$A:$F,6,FALSE) -> Yes | H1338: =VLOOKUP(A1338,'Clinical Assessments (2)'!$A:$G,7,FALSE) -> 1 | I1338: =VLOOKUP(A1338,'Clinical Assessments (2)'!$A:$H,8,FALSE) -> No | J1338: =IF(C1338<18.5,"Under weight",IF(C1338<25,"Normal weight",IF(C1338<30,"Over weight","Obesity"))) -> Obesity | K1338: =IF('Patient Insights'!D1338<5.7,"Normal",IF('Patient Insights'!D1338<6.5,"Prediabetes","Diabetes")) -> Diabetes | L1338: =IFERROR(VLOOKUP(Admission_Records[[#This Row],[Admission Year]],'Admission Records (2)'!$B:$D,3,FALSE),Admission_Records[[#This Row],[Admission Day]]) -> 10 | M1338: =IFERROR(VLOOKUP(A1338,'Admission Records (2)'!$A:$G,7,FALSE),"Unknown") -> 2630.61 | N1338: =IFERROR(VLOOKUP(A1338,'Admission Records (2)'!$A:$H,8,FALSE),"Unknown") -> Tier 2 | O1338: =IFERROR(VLOOKUP(A1338,'Admission Records (2)'!$A:$I,9,FALSE),"Unknown") -> Tier 2 | P1338: =IFERROR(VLOOKUP(A1338,'Admission Records (2)'!$A:$J,10,FALSE),"Unknown") -> ZN2013
A1339: PT01338 | B1339: =VLOOKUP(A1339,'Patient Directory (2)'!$A:$B,2,FALSE) -> Austin Walker | C1339: =VLOOKUP(A1339,'Clinical Assessments (2)'!$A:$B,2,FALSE) -> 33.97 | D1339: =VLOOKUP(A1339,'Clinical Assessments (2)'!$A:$C,3,FALSE) -> 7.28 | E1339: =VLOOKUP(A1339,'Clinical Assessments (2)'!$A:$D,4,FALSE) -> No | F1339: =VLOOKUP(A1339,'Clinical Assessments (2)'!$A:$E,5,FALSE) -> No | G1339: =VLOOKUP(A1339,'Clinical Assessments (2)'!$A:$F,6,FALSE) -> No | H1339: =VLOOKUP(A1339,'Clinical Assessments (2)'!$A:$G,7,FALSE) -> 0 | I1339: =VLOOKUP(A1339,'Clinical Assessments (2)'!$A:$H,8,FALSE) -> Yes | J1339: =IF(C1339<18.5,"Under weight",IF(C1339<25,"Normal weight",IF(C1339<30,"Over weight","Obesity"))) -> Obesity | K1339: =IF('Patient Insights'!D1339<5.7,"Normal",IF('Patient Insights'!D1339<6.5,"Prediabetes","Diabetes")) -> Diabetes | L1339: =IFERROR(VLOOKUP(Admission_Records[[#This Row],[Admission Year]],'Admission Records (2)'!$B:$D,3,FALSE),Admission_Records[[#This Row],[Admission Day]]) -> 14 | M1339: =IFERROR(VLOOKUP(A1339,'Admission Records (2)'!$A:$G,7,FALSE),"Unknown") -> 4018.32 | N1339: =IFERROR(VLOOKUP(A1339,'Admission Records (2)'!$A:$H,8,FALSE),"Unknown") -> Tier 3 | O1339: =IFERROR(VLOOKUP(A1339,'Admission Records (2)'!$A:$I,9,FALSE),"Unknown") -> Tier 2 | P1339: =IFERROR(VLOOKUP(A1339,'Admission Records (2)'!$A:$J,10,FALSE),"Unknown") -> ZN2007
A1340: PT01339 | B1340: =VLOOKUP(A1340,'Patient Directory (2)'!$A:$B,2,FALSE) -> Andrew Cruz | C1340: =VLOOKUP(A1340,'Clinical Assessments (2)'!$A:$B,2,FALSE) -> 47.93 | D1340: =VLOOKUP(A1340,'Clinical Assessments (2)'!$A:$C,3,FALSE) -> 4 | E1340: =VLOOKUP(A1340,'Clinical Assessments (2)'!$A:$D,4,FALSE) -> No | F1340: =VLOOKUP(A1340,'Clinical Assessments (2)'!$A:$E,5,FALSE) -> No | G1340: =VLOOKUP(A1340,'Clinical Assessments (2)'!$A:$F,6,FALSE) -> No | H1340: =VLOOKUP(A1340,'Clinical Assessments (2)'!$A:$G,7,FALSE) -> 1 | I1340: =VLOOKUP(A1340,'Clinical Assessments (2)'!$A:$H,8,FALSE) -> No | J1340: =IF(C1340<18.5,"Under weight",IF(C1340<25,"Normal weight",IF(C1340<30,"Over weight","Obesity"))) -> Obesity | K1340: =IF('Patient Insights'!D1340<5.7,"Normal",IF('Patient Insights'!D1340<6.5,"Prediabetes","Diabetes")) -> Normal | L1340: =IFERROR(VLOOKUP(Admission_Records[[#This Row],[Admission Year]],'Admission Records (2)'!$B:$D,3,FALSE),Admission_Records[[#This Row],[Admission Day]]) -> 18 | M1340: =IFERROR(VLOOKUP(A1340,'Admission Records (2)'!$A:$G,7,FALSE),"Unknown") -> 17528.25 | N1340: =IFERROR(VLOOKUP(A1340,'Admission Records (2)'!$A:$H,8,FALSE),"Unknown") -> Tier 1 | O1340: =IFERROR(VLOOKUP(A1340,'Admission Records (2)'!$A:$I,9,FALSE),"Unknown") -> Tier 2 | P1340: =IFERROR(VLOOKUP(A1340,'Admission Records (2)'!$A:$J,10,FALSE),"Unknown") -> ZN2014
A1341: PT01340 | B1341: =VLOOKUP(A1341,'Patient Directory (2)'!$A:$B,2,FALSE) -> Miss Kelly Dawson | C1341: =VLOOKUP(A1341,'Clinical Assessments (2)'!$A:$B,2,FALSE) -> 28.05 | D1341: =VLOOKUP(A1341,'Clinical Assessments (2)'!$A:$C,3,FALSE) -> 4 | E1341: =VLOOKUP(A1341,'Clinical Assessments (2)'!$A:$D,4,FALSE) -> No | F1341: =VLOOKUP(A1341,'Clinical Assessments (2)'!$A:$E,5,FALSE) -> No | G1341: =VLOOKUP(A1341,'Clinical Assessments (2)'!$A:$F,6,FALSE) -> No | H1341: =VLOOKUP(A1341,'Clinical Assessments (2)'!$A:$G,7,FALSE) -> 2 | I1341: =VLOOKUP(A1341,'Clinical Assessments (2)'!$A:$H,8,FALSE) -> Yes | J1341: =IF(C1341<18.5,"Under weight",IF(C1341<25,"Normal weight",IF(C1341<30,"Over weight","Obesity"))) -> Over weight | K1341: =IF('Patient Insights'!D1341<5.7,"Normal",IF('Patient Insights'!D1341<6.5,"Prediabetes","Diabetes")) -> Normal | L1341: =IFERROR(VLOOKUP(Admission_Records[[#This Row],[Admission Year]],'Admission Records (2)'!$B:$D,3,FALSE),Admission_Records[[#This Row],[Admission Day]]) -> 19 | M1341: =IFERROR(VLOOKUP(A1341,'Admission Records (2)'!$A:$G,7,FALSE),"Unknown") -> 16668.44 | N1341: =IFERROR(VLOOKUP(A1341,'Admission Records (2)'!$A:$H,8,FALSE),"Unknown") -> Tier 1 | O1341: =IFERROR(VLOOKUP(A1341,'Admission Records (2)'!$A:$I,9,FALSE),"Unknown") -> Tier 3 | P1341: =IFERROR(VLOOKUP(A1341,'Admission Records (2)'!$A:$J,10,FALSE),"Unknown") -> ZN2004
A1342: PT01341 | B1342: =VLOOKUP(A1342,'Patient Directory (2)'!$A:$B,2,FALSE) -> Theresa Wilkins | C1342: =VLOOKUP(A1342,'Clinical Assessments (2)'!$A:$B,2,FALSE) -> 24.07 | D1342: =VLOOKUP(A1342,'Clinical Assessments (2)'!$A:$C,3,FALSE) -> 9.95 | E1342: =VLOOKUP(A1342,'Clinical Assessments (2)'!$A:$D,4,FALSE) -> No | F1342: =VLOOKUP(A1342,'Clinical Assessments (2)'!$A:$E,5,FALSE) -> No | G1342: =VLOOKUP(A1342,'Clinical Assessments (2)'!$A:$F,6,FALSE) -> No | H1342: =VLOOKUP(A1342,'Clinical Assessments (2)'!$A:$G,7,FALSE) -> 0 | I1342: =VLOOKUP(A1342,'Clinical Assessments (2)'!$A:$H,8,FALSE) -> No | J1342: =IF(C1342<18.5,"Under weight",IF(C1342<25,"Normal weight",IF(C1342<30,"Over weight","Obesity"))) -> Normal weight | K1342: =IF('Patient Insights'!D1342<5.7,"Normal",IF('Patient Insights'!D1342<6.5,"Prediabetes","Diabetes")) -> Diabetes | L1342: =IFERROR(VLOOKUP(Admission_Records[[#This Row],[Admission Year]],'Admission Records (2)'!$B:$D,3,FALSE),Admission_Records[[#This Row],[Admission Day]]) -> 4 | M1342: =IFERROR(VLOOKUP(A1342,'Admission Records (2)'!$A:$G,7,FALSE),"Unknown") -> Unknown | N1342: =IFERROR(VLOOKUP(A1342,'Admission Records (2)'!$A:$H,8,FALSE),"Unknown") -> Unknown | O1342: =IFERROR(VLOOKUP(A1342,'Admission Records (2)'!$A:$I,9,FALSE),"Unknown") -> Unknown | P1342: =IFERROR(VLOOKUP(A1342,'Admission Records (2)'!$A:$J,10,FALSE),"Unknown") -> Unknown
A1343: PT01342 | B1343: =VLOOKUP(A1343,'Patient Directory (2)'!$A:$B,2,FALSE) -> Jessica Harris | C1343: =VLOOKUP(A1343,'Clinical Assessments (2)'!$A:$B,2,FALSE) -> 32.41 | D1343: =VLOOKUP(A1343,'Clinical Assessments (2)'!$A:$C,3,FALSE) -> 4.21 | E1343: =VLOOKUP(A1343,'Clinical Assessments (2)'!$A:$D,4,FALSE) -> No | F1343: =VLOOKUP(A1343,'Clinical Assessments (2)'!$A:$E,5,FALSE) -> No | G1343: =VLOOKUP(A1343,'Clinical Assessments (2)'!$A:$F,6,FALSE) -> Yes | H1343: =VLOOKUP(A1343,'Clinical Assessments (2)'!$A:$G,7,FALSE) -> 1 | I1343: =VLOOKUP(A1343,'Clinical Assessments (2)'!$A:$H,8,FALSE) -> No | J1343: =IF(C1343<18.5,"Under weight",IF(C1343<25,"Normal weight",IF(C1343<30,"Over weight","Obesity"))) -> Obesity | K1343: =IF('Patient Insights'!D1343<5.7,"Normal",IF('Patient Insights'!D1343<6.5,"Prediabetes","Diabetes")) -> Normal | L1343: =IFERROR(VLOOKUP(Admission_Records[[#This Row],[Admission Year]],'Admission Records (2)'!$B:$D,3,FALSE),Admission_Records[[#This Row],[Admission Day]]) -> 1 | M1343: =IFERROR(VLOOKUP(A1343,'Admission Records (2)'!$A:$G,7,FALSE),"Unknown") -> 4750.29 | N1343: =IFERROR(VLOOKUP(A1343,'Admission Records (2)'!$A:$H,8,FALSE),"Unknown") -> Tier 1 | O1343: =IFERROR(VLOOKUP(A1343,'Admission Records (2)'!$A:$I,9,FALSE),"Unknown") -> Tier 1 | P1343: =IFERROR(VLOOKUP(A1343,'Admission Records (2)'!$A:$J,10,FALSE),"Unknown") -> ZN2018
A1344: PT01343 | B1344: =VLOOKUP(A1344,'Patient Directory (2)'!$A:$B,2,FALSE) -> Regina Mitchell | C1344: =VLOOKUP(A1344,'Clinical Assessments (2)'!$A:$B,2,FALSE) -> 32.49 | D1344: =VLOOKUP(A1344,'Clinical Assessments (2)'!$A:$C,3,FALSE) -> 7.36 | E1344: =VLOOKUP(A1344,'Clinical Assessments (2)'!$A:$D,4,FALSE) -> No | F1344: =VLOOKUP(A1344,'Clinical Assessments (2)'!$A:$E,5,FALSE) -> No | G1344: =VLOOKUP(A1344,'Clinical Assessments (2)'!$A:$F,6,FALSE) -> No | H1344: =VLOOKUP(A1344,'Clinical Assessments (2)'!$A:$G,7,FALSE) -> 0 | I1344: =VLOOKUP(A1344,'Clinical Assessments (2)'!$A:$H,8,FALSE) -> No | J1344: =IF(C1344<18.5,"Under weight",IF(C1344<25,"Normal weight",IF(C1344<30,"Over weight","Obesity"))) -> Obesity | K1344: =IF('Patient Insights'!D1344<5.7,"Normal",IF('Patient Insights'!D1344<6.5,"Prediabetes","Diabetes")) -> Diabetes | L1344: =IFERROR(VLOOKUP(Admission_Records[[#This Row],[Admission Year]],'Admission Records (2)'!$B:$D,3,FALSE),Admission_Records[[#This Row],[Admission Day]]) -> 10 | M1344: =IFERROR(VLOOKUP(A1344,'Admission Records (2)'!$A:$G,7,FALSE),"Unknown") -> Unknown | N1344: =IFERROR(VLOOKUP(A1344,'Admission Records (2)'!$A:$H,8,FALSE),"Unknown") -> Unknown | O1344: =IFERROR(VLOOKUP(A1344,'Admission Records (2)'!$A:$I,9,FALSE),"Unknown") -> Unknown | P1344: =IFERROR(VLOOKUP(A1344,'Admission Records (2)'!$A:$J,10,FALSE),"Unknown") -> Unknown
A1345: PT01344 | B1345: =VLOOKUP(A1345,'Patient Directory (2)'!$A:$B,2,FALSE) -> Kyle Black | C1345: =VLOOKUP(A1345,'Clinical Assessments (2)'!$A:$B,2,FALSE) -> 25.92 | D1345: =VLOOKUP(A1345,'Clinical Assessments (2)'!$A:$C,3,FALSE) -> 4.89 | E1345: =VLOOKUP(A1345,'Clinical Assessments (2)'!$A:$D,4,FALSE) -> No | F1345: =VLOOKUP(A1345,'Clinical Assessments (2)'!$A:$E,5,FALSE) -> No | G1345: =VLOOKUP(A1345,'Clinical Assessments (2)'!$A:$F,6,FALSE) -> No | H1345: =VLOOKUP(A1345,'Clinical Assessments (2)'!$A:$G,7,FALSE) -> 3 | I1345: =VLOOKUP(A1345,'Clinical Assessments (2)'!$A:$H,8,FALSE) -> No | J1345: =IF(C1345<18.5,"Under weight",IF(C1345<25,"Normal weight",IF(C1345<30,"Over weight","Obesity"))) -> Over weight | K1345: =IF('Patient Insights'!D1345<5.7,"Normal",IF('Patient Insights'!D1345<6.5,"Prediabetes","Diabetes")) -> Normal | L1345: =IFERROR(VLOOKUP(Admission_Records[[#This Row],[Admission Year]],'Admission Records (2)'!$B:$D,3,FALSE),Admission_Records[[#This Row],[Admission Day]]) -> 14 | M1345: =IFERROR(VLOOKUP(A1345,'Admission Records (2)'!$A:$G,7,FALSE),"Unknown") -> Unknown | N1345: =IFERROR(VLOOKUP(A1345,'Admission Records (2)'!$A:$H,8,FALSE),"Unknown") -> Unknown | O1345: =IFERROR(VLOOKUP(A1345,'Admission Records (2)'!$A:$I,9,FALSE),"Unknown") -> Unknown | P1345: =IFERROR(VLOOKUP(A1345,'Admission Records (2)'!$A:$J,10,FALSE),"Unknown") -> Unknown
A1346: PT01345 | B1346: =VLOOKUP(A1346,'Patient Directory (2)'!$A:$B,2,FALSE) -> Christopher Johnson | C1346: =VLOOKUP(A1346,'Clinical Assessments (2)'!$A:$B,2,FALSE) -> 22.48 | D1346: =VLOOKUP(A1346,'Clinical Assessments (2)'!$A:$C,3,FALSE) -> 6.35 | E1346: =VLOOKUP(A1346,'Clinical Assessments (2)'!$A:$D,4,FALSE) -> No | F1346: =VLOOKUP(A1346,'Clinical Assessments (2)'!$A:$E,5,FALSE) -> No | G1346: =VLOOKUP(A1346,'Clinical Assessments (2)'!$A:$F,6,FALSE) -> No | H1346: =VLOOKUP(A1346,'Clinical Assessments (2)'!$A:$G,7,FALSE) -> 0 | I1346: =VLOOKUP(A1346,'Clinical Assessments (2)'!$A:$H,8,FALSE) -> No | J1346: =IF(C1346<18.5,"Under weight",IF(C1346<25,"Normal weight",IF(C1346<30,"Over weight","Obesity"))) -> Normal weight | K1346: =IF('Patient Insights'!D1346<5.7,"Normal",IF('Patient Insights'!D1346<6.5,"Prediabetes","Diabetes")) -> Prediabetes | L1346: =IFERROR(VLOOKUP(Admission_Records[[#This Row],[Admission Year]],'Admission Records (2)'!$B:$D,3,FALSE),Admission_Records[[#This Row],[Admission Day]]) -> 12 | M1346: =IFERROR(VLOOKUP(A1346,'Admission Records (2)'!$A:$G,7,FALSE),"Unknown") -> Unknown | N1346: =IFERROR(VLOOKUP(A1346,'Admission Records (2)'!$A:$H,8,FALSE),"Unknown") -> Unknown | O1346: =IFERROR(VLOOKUP(A1346,'Admission Records (2)'!$A:$I,9,FALSE),"Unknown") -> Unknown | P1346: =IFERROR(VLOOKUP(A1346,'Admission Records (2)'!$A:$J,10,FALSE),"Unknown") -> Unknown
A1347: PT01346 | B1347: =VLOOKUP(A1347,'Patient Directory (2)'!$A:$B,2,FALSE) -> Aaron Moore | C1347: =VLOOKUP(A1347,'Clinical Assessments (2)'!$A:$B,2,FALSE) -> 45.21 | D1347: =VLOOKUP(A1347,'Clinical Assessments (2)'!$A:$C,3,FALSE) -> 5 | E1347: =VLOOKUP(A1347,'Clinical Assessments (2)'!$A:$D,4,FALSE) -> No | F1347: =VLOOKUP(A1347,'Clinical Assessments (2)'!$A:$E,5,FALSE) -> No | G1347: =VLOOKUP(A1347,'Clinical Assessments (2)'!$A:$F,6,FALSE) -> No | H1347: =VLOOKUP(A1347,'Clinical Assessments (2)'!$A:$G,7,FALSE) -> 0 | I1347: =VLOOKUP(A1347,'Clinical Assessments (2)'!$A:$H,8,FALSE) -> No | J1347: =IF(C1347<18.5,"Under weight",IF(C1347<25,"Normal weight",IF(C1347<30,"Over weight","Obesity"))) -> Obesity | K1347: =IF('Patient Insights'!D1347<5.7,"Normal",IF('Patient Insights'!D1347<6.5,"Prediabetes","Diabetes")) -> Normal | L1347: =IFERROR(VLOOKUP(Admission_Records[[#This Row],[Admission Year]],'Admission Records (2)'!$B:$D,3,FALSE),Admission_Records[[#This Row],[Admission Day]]) -> 19 | M1347: =IFERROR(VLOOKUP(A1347,'Admission Records (2)'!$A:$G,7,FALSE),"Unknown") -> Unknown | N1347: =IFERROR(VLOOKUP(A1347,'Admission Records (2)'!$A:$H,8,FALSE),"Unknown") -> Unknown | O1347: =IFERROR(VLOOKUP(A1347,'Admission Records (2)'!$A:$I,9,FALSE),"Unknown") -> Unknown | P1347: =IFERROR(VLOOKUP(A1347,'Admission Records (2)'!$A:$J,10,FALSE),"Unknown") -> Unknown
A1348: PT01347 | B1348: =VLOOKUP(A1348,'Patient Directory (2)'!$A:$B,2,FALSE) -> Penny Gomez Md | C1348: =VLOOKUP(A1348,'Clinical Assessments (2)'!$A:$B,2,FALSE) -> 31.72 | D1348: =VLOOKUP(A1348,'Clinical Assessments (2)'!$A:$C,3,FALSE) -> 7.27 | E1348: =VLOOKUP(A1348,'Clinical Assessments (2)'!$A:$D,4,FALSE) -> No | F1348: =VLOOKUP(A1348,'Clinical Assessments (2)'!$A:$E,5,FALSE) -> No | G1348: =VLOOKUP(A1348,'Clinical Assessments (2)'!$A:$F,6,FALSE) -> No | H1348: =VLOOKUP(A1348,'Clinical Assessments (2)'!$A:$G,7,FALSE) -> 0 | I1348: =VLOOKUP(A1348,'Clinical Assessments (2)'!$A:$H,8,FALSE) -> Yes | J1348: =IF(C1348<18.5,"Under weight",IF(C1348<25,"Normal weight",IF(C1348<30,"Over weight","Obesity"))) -> Obesity | K1348: =IF('Patient Insights'!D1348<5.7,"Normal",IF('Patient Insights'!D1348<6.5,"Prediabetes","Diabetes")) -> Diabetes | L1348: =IFERROR(VLOOKUP(Admission_Records[[#This Row],[Admission Year]],'Admission Records (2)'!$B:$D,3,FALSE),Admission_Records[[#This Row],[Admission Day]]) -> 10 | M1348: =IFERROR(VLOOKUP(A1348,'Admission Records (2)'!$A:$G,7,FALSE),"Unknown") -> Unknown | N1348: =IFERROR(VLOOKUP(A1348,'Admission Records (2)'!$A:$H,8,FALSE),"Unknown") -> Unknown | O1348: =IFERROR(VLOOKUP(A1348,'Admission Records (2)'!$A:$I,9,FALSE),"Unknown") -> Unknown | P1348: =IFERROR(VLOOKUP(A1348,'Admission Records (2)'!$A:$J,10,FALSE),"Unknown") -> Unknown
A1349: PT01348 | B1349: =VLOOKUP(A1349,'Patient Directory (2)'!$A:$B,2,FALSE) -> Kelly Mclaughlin | C1349: =VLOOKUP(A1349,'Clinical Assessments (2)'!$A:$B,2,FALSE) -> 24.52 | D1349: =VLOOKUP(A1349,'Clinical Assessments (2)'!$A:$C,3,FALSE) -> 6.46 | E1349: =VLOOKUP(A1349,'Clinical Assessments (2)'!$A:$D,4,FALSE) -> No | F1349: =VLOOKUP(A1349,'Clinical Assessments (2)'!$A:$E,5,FALSE) -> No | G1349: =VLOOKUP(A1349,'Clinical Assessments (2)'!$A:$F,6,FALSE) -> No | H1349: =VLOOKUP(A1349,'Clinical Assessments (2)'!$A:$G,7,FALSE) -> 2 | I1349: =VLOOKUP(A1349,'Clinical Assessments (2)'!$A:$H,8,FALSE) -> No | J1349: =IF(C1349<18.5,"Under weight",IF(C1349<25,"Normal weight",IF(C1349<30,"Over weight","Obesity"))) -> Normal weight | K1349: =IF('Patient Insights'!D1349<5.7,"Normal",IF('Patient Insights'!D1349<6.5,"Prediabetes","Diabetes")) -> Prediabetes | L1349: =IFERROR(VLOOKUP(Admission_Records[[#This Row],[Admission Year]],'Admission Records (2)'!$B:$D,3,FALSE),Admission_Records[[#This Row],[Admission Day]]) -> 14 | M1349: =IFERROR(VLOOKUP(A1349,'Admission Records (2)'!$A:$G,7,FALSE),"Unknown") -> Unknown | N1349: =IFERROR(VLOOKUP(A1349,'Admission Records (2)'!$A:$H,8,FALSE),"Unknown") -> Unknown | O1349: =IFERROR(VLOOKUP(A1349,'Admission Records (2)'!$A:$I,9,FALSE),"Unknown") -> Unknown | P1349: =IFERROR(VLOOKUP(A1349,'Admission Records (2)'!$A:$J,10,FALSE),"Unknown") -> Unknown
... A2336: PT02335 | B2336: =VLOOKUP(A2336,'Patient Directory (2)'!$A:$B,2,FALSE) -> Scott Stewart | C2336: =VLOOKUP(A2336,'Clinical Assessments (2)'!$A:$B,2,FALSE) -> 26.16 | D2336: =VLOOKUP(A2336,'Clinical Assessments (2)'!$A:$C,3,FALSE) -> 4.7 | E2336: =VLOOKUP(A2336,'Clinical Assessments (2)'!$A:$D,4,FALSE) -> No | F2336: =VLOOKUP(A2336,'Clinical Assessments (2)'!$A:$E,5,FALSE) -> No | G2336: =VLOOKUP(A2336,'Clinical Assessments (2)'!$A:$F,6,FALSE) -> No | H2336: =VLOOKUP(A2336,'Clinical Assessments (2)'!$A:$G,7,FALSE) -> 0 | I2336: =VLOOKUP(A2336,'Clinical Assessments (2)'!$A:$H,8,FALSE) -> Yes | J2336: =IF(C2336<18.5,"Under weight",IF(C2336<25,"Normal weight",IF(C2336<30,"Over weight","Obesity"))) -> Over weight | K2336: =IF('Patient Insights'!D2336<5.7,"Normal",IF('Patient Insights'!D2336<6.5,"Prediabetes","Diabetes")) -> Normal | L2336: =IFERROR(VLOOKUP(Admission_Records[[#This Row],[Admission Year]],'Admission Records (2)'!$B:$D,3,FALSE),Admission_Records[[#This Row],[Admission Day]]) -> 14 | M2336: =IFERROR(VLOOKUP(A2336,'Admission Records (2)'!$A:$G,7,FALSE),"Unknown") -> 4058.06 | N2336: =IFERROR(VLOOKUP(A2336,'Admission Records (2)'!$A:$H,8,FALSE),"Unknown") -> Tier 2 | O2336: =IFERROR(VLOOKUP(A2336,'Admission Records (2)'!$A:$I,9,FALSE),"Unknown") -> Tier 2 | P2336: =IFERROR(VLOOKUP(A2336,'Admission Records (2)'!$A:$J,10,FALSE),"Unknown") -> ZN2007

Sheet PIVOT TABLE
B3: Count of Patient ID | C3: Column Labels | G3: Row Labels | H3: Sum of Major Surgeries Count | I3: Average of HbA1c Level
B4: Row Labels | C4: No | D4: Yes | E4: Grand Total | G4: No | H4: 1862 | I4: 6.3415495
B5: No | C5: 1603 | D5: 195 | E5: 1798 | G5: Yes | H5: 90 | I5: 6.2292157
B6: Yes | C6: 467 | D6: 70 | E6: 537 | G6: Grand Total | H6: 1952 | I6: 6.3366424
B7: Grand Total | C7: 2070 | D7: 265 | E7: 2335
B9: Average of Billed Amount | C9: Column Labels | H9: Average of Billed Amount | I9: Column Labels
B10: Row Labels | C10: Tier 1 | D10: Tier 2 | E10: Tier 3 | F10: Grand Total | H10: Row Labels | I10: Tier 1 | J10: Tier 2 | K10: Tier 3 | L10: Grand Total
B11: Normal weight | C11: 10149.544 | D11: 9917.1294 | E11: 10012.225 | F11: 9998.7708 | H11: Unknown | I11: 7193.2414 | J11: 10681.514 | K11: 5883.908 | L11: 8261.217
B12: Grand Total | C12: 10149.544 | D12: 9917.1294 | E12: 10012.225 | F12: 9998.7708 | H12: ZN2001 | I12: 8698.0528 | J12: 10224.654 | K12: 8739.2715 | L12: 9538.6639
H13: ZN2002 | I13: 11119.618 | J13: 9060.7078 | K13: 11539.402 | L13: 10268.976
H14: ZN2003 | I14: 8040.4508 | J14: 8501.8848 | K14: 8965.1806 | L14: 8544.4257
H15: ZN2004 | I15: 11283.737 | J15: 9536.1238 | K15: 8796.9954 | L15: 9882.9234
H16: ZN2005 | I16: 11347.522 | J16: 9778.3486 | K16: 8810.3422 | L16: 9950.6137
H17: ZN2006 | I17: 9608.1439 | J17: 7746.6644 | K17: 11426.391 | L17: 9055.1842
H18: ZN2007 | I18: 12639.858 | J18: 10255.985 | K18: 10479.23 | L18: 10918.631
H19: ZN2008 | I19: 9862.6147 | J19: 9416.2839 | K19: 12254.905 | L19: 10049.167
H20: ZN2009 | I20: 7565.8237 | J20: 9072.696 | K20: 10323.805 | L20: 8820.9226
H21: ZN2010 | I21: 8352.2458 | J21: 9379.8633 | K21: 14017.257 | L21: 9992.285
H22: ZN2011 | I22: 10499.775 | J22: 9504.38 | K22: 8493.3619 | L22: 9562.8401
H23: ZN2012 | I23: 9674.7588 | J23: 10358.005 | K23: 12864.065 | L23: 10692.208
H24: ZN2013 | I24: 11175.009 | J24: 11329.074 | K24: 8231.5123 | L24: 10764.182
... H31: Grand Total | I31: 10149.544 | J31: 9917.1294 | K31: 10012.225 | L31: 9998.7708

Sheet DASHBOARD
A1: PATIENT INSURANCE SYNTHETIC HEALTHCARE DASBOARD
